#VRML_SIM R2023b utf8

EXTERNPROTO "https://raw.githubusercontent.com/cyberbotics/webots/R2022b/projects/objects/backgrounds/protos/TexturedBackground.proto"
EXTERNPROTO "https://raw.githubusercontent.com/cyberbotics/webots/R2022b/projects/objects/backgrounds/protos/TexturedBackgroundLight.proto"
EXTERNPROTO "https://raw.githubusercontent.com/cyberbotics/webots/R2022b/projects/objects/floors/protos/RectangleArena.proto"
EXTERNPROTO "https://raw.githubusercontent.com/cyberbotics/webots/R2022b/projects/devices/robotiq/protos/Robotiq3fGripper.proto"

WorldInfo {
}
Viewpoint {
  orientation 0.15134473226556666 -0.39371964246773533 -0.9066860620691941 5.481190408252046
  position -2.1974195583430154 -3.757975069053541 1.6548023119902873
}
TexturedBackground {
}
TexturedBackgroundLight {
}
Solid {
  translation 0.49 -0.75 0
  children [
    Shape {
      appearance PBRAppearance {
      }
      geometry Box {
        size 0.1 0.1 0.1
      }
    }
  ]
}
RectangleArena {
  floorSize 10 10
}
Robot {
  rotation 0 0 1 3.14159
  children [
    Pose {
      translation -0.0602 0.0601 0.0252
      rotation 1 0 0 -3.1415923071795864
      children [
        DEF SCREW Group {
          children [
            Transform {
              scale 1.1 1.1 1.1
              children [
                Shape {
                  appearance PBRAppearance {
                    baseColorMap ImageTexture {
                      url [
                        "https://raw.githubusercontent.com/cyberbotics/webots/R2022b/projects/appearances/protos/textures/old_steel/old_steel_base_color.jpg"
                      ]
                    }
                    roughnessMap ImageTexture {
                      url [
                        "https://raw.githubusercontent.com/cyberbotics/webots/R2022b/projects/appearances/protos/textures/old_steel/old_steel_roughness.jpg"
                      ]
                    }
                    metalnessMap ImageTexture {
                      url [
                        "https://raw.githubusercontent.com/cyberbotics/webots/R2022b/projects/appearances/protos/textures/old_steel/old_steel_metalness.jpg"
                      ]
                    }
                    normalMap ImageTexture {
                      url [
                        "https://raw.githubusercontent.com/cyberbotics/webots/R2022b/projects/appearances/protos/textures/old_steel/old_steel_normal.jpg"
                      ]
                    }
                  }
                  geometry Mesh {
                    url [
                      "https://raw.githubusercontent.com/cyberbotics/webots/R2022b/projects/robots/universal_robots/protos/UR10e/meshes/screw.obj"
                    ]
                  }
                }
              ]
            }
            DEF CYLINDER Pose {
              translation 0 0 0.02
              rotation -0.7071067811865476 0.7071067811865476 0 -3.141593
              children [
                Shape {
                  appearance PBRAppearance {
                    baseColorMap ImageTexture {
                      url [
                        "https://raw.githubusercontent.com/cyberbotics/webots/R2022b/projects/appearances/protos/textures/screw_thread/screw_thread_base_color.jpg"
                      ]
                    }
                    roughnessMap ImageTexture {
                      url [
                        "https://raw.githubusercontent.com/cyberbotics/webots/R2022b/projects/appearances/protos/textures/screw_thread/screw_thread_roughness.jpg"
                      ]
                    }
                    normalMap ImageTexture {
                      url [
                        "https://raw.githubusercontent.com/cyberbotics/webots/R2022b/projects/appearances/protos/textures/screw_thread/screw_thread_normal.jpg"
                      ]
                    }
                    occlusionMap ImageTexture {
                      url [
                        "https://raw.githubusercontent.com/cyberbotics/webots/R2022b/projects/appearances/protos/textures/screw_thread/screw_thread_occlusion.jpg"
                      ]
                    }
                    textureTransform TextureTransform {
                      rotation 1.5708
                      scale 1.6 2
                    }
                  }
                  geometry Cylinder {
                    height 0.04
                    radius 0.0044
                  }
                }
              ]
            }
          ]
        }
      ]
    }
    Pose {
      translation -0.0602 -0.0602 0.0252
      rotation 1 0 0 -3.1415923071795864
      children [
        USE SCREW
      ]
    }
    Pose {
      translation 0.0602 -0.0602 0.0252
      rotation 1 0 0 -3.1415923071795864
      children [
        USE SCREW
      ]
    }
    Pose {
      translation 0.0602 0.0602 0.0252
      rotation 1 0 0 -3.1415923071795864
      children [
        USE SCREW
      ]
    }
    Shape {
      appearance DEF METAL_APPEARANCE PBRAppearance {
        baseColor 0.6 0.6 0.6
        roughness 0.7
      }
      geometry Mesh {
        url [
          "https://raw.githubusercontent.com/cyberbotics/webots/R2022b/projects/robots/universal_robots/protos/UR10e/meshes/base_link_0.obj"
        ]
      }
    }
    Shape {
      appearance DEF JOINT_APPEARANCE PBRAppearance {
        baseColor 0 0 0
        roughness 1
        metalness 0
      }
      geometry Mesh {
        url [
          "https://raw.githubusercontent.com/cyberbotics/webots/R2022b/projects/robots/universal_robots/protos/UR10e/meshes/base_link_1.obj"
        ]
      }
    }
    HingeJoint {
      jointParameters HingeJointParameters {
        position 2.8100225021482834
        axis 0 0 1
        anchor 0 0 0.181
      }
      device [
        RotationalMotor {
          name "shoulder_pan_joint"
          maxVelocity 3.14
          minPosition -6.28318530718
          maxPosition 6.28318530718
          maxTorque 330
        }
        PositionSensor {
          name "shoulder_pan_joint_sensor"
        }
      ]
      endPoint Solid {
        translation 0 0 0.181
        rotation 0 0 1 5.951607809327871
        children [
          Shape {
            appearance DEF SCREW_APPEARANCE PBRAppearance {
            }
            geometry Mesh {
              url [
                "https://raw.githubusercontent.com/cyberbotics/webots/R2022b/projects/robots/universal_robots/protos/UR10e/meshes/shoulder_link_0.obj"
              ]
            }
          }
          Shape {
            appearance USE METAL_APPEARANCE
            geometry Mesh {
              url [
                "https://raw.githubusercontent.com/cyberbotics/webots/R2022b/projects/robots/universal_robots/protos/UR10e/meshes/shoulder_link_1.obj"
              ]
            }
          }
          Shape {
            appearance USE JOINT_APPEARANCE
            geometry Mesh {
              url [
                "https://raw.githubusercontent.com/cyberbotics/webots/R2022b/projects/robots/universal_robots/protos/UR10e/meshes/shoulder_link_2.obj"
              ]
            }
          }
          Shape {
            appearance PBRAppearance {
              baseColor 0.490196 0.678431 0.8
              roughness 0.96875
              metalness 0
              normalMap ImageTexture {
                url [
                  "https://raw.githubusercontent.com/cyberbotics/webots/R2022b/projects/robots/universal_robots/protos/UR10e/textures/normal_0.jpg"
                ]
              }
              occlusionMap ImageTexture {
                url [
                  "https://raw.githubusercontent.com/cyberbotics/webots/R2022b/projects/robots/universal_robots/protos/UR10e/textures/occlusion_0.jpg"
                ]
              }
            }
            geometry Mesh {
              url [
                "https://raw.githubusercontent.com/cyberbotics/webots/R2022b/projects/robots/universal_robots/protos/UR10e/meshes/shoulder_link_3.obj"
              ]
            }
          }
          HingeJoint {
            jointParameters HingeJointParameters {
              position -2.3705883361335394
              axis 0 1 0
              anchor 0 0.176 0
            }
            device [
              RotationalMotor {
                name "shoulder_lift_joint"
                maxVelocity 3.14
                minPosition -6.28318530718
                maxPosition 6.28318530718
                maxTorque 330
              }
              PositionSensor {
                name "shoulder_lift_joint_sensor"
              }
            ]
            endPoint Solid {
              translation 0 0.176 0
              rotation 0 -0.9999999999999999 0 0.7997923361335396
              children [
                Shape {
                  appearance USE SCREW_APPEARANCE
                  geometry Mesh {
                    url [
                      "https://raw.githubusercontent.com/cyberbotics/webots/R2022b/projects/robots/universal_robots/protos/UR10e/meshes/upper_arm_link_0.obj"
                    ]
                  }
                }
                Shape {
                  appearance USE SCREW_APPEARANCE
                  geometry Mesh {
                    url [
                      "https://raw.githubusercontent.com/cyberbotics/webots/R2022b/projects/robots/universal_robots/protos/UR10e/meshes/upper_arm_link_1.obj"
                    ]
                  }
                }
                Shape {
                  appearance DEF METAL_APPEARANCE_LIGHT PBRAppearance {
                    roughness 0.7
                  }
                  geometry Mesh {
                    url [
                      "https://raw.githubusercontent.com/cyberbotics/webots/R2022b/projects/robots/universal_robots/protos/UR10e/meshes/upper_arm_link_2.obj"
                    ]
                  }
                }
                Shape {
                  appearance PBRAppearance {
                    baseColor 0.490196 0.678431 0.8
                    roughness 0.96875
                    metalness 0
                    normalMap ImageTexture {
                      url [
                        "https://raw.githubusercontent.com/cyberbotics/webots/R2022b/projects/robots/universal_robots/protos/UR10e/textures/normal_1.jpg"
                      ]
                    }
                    occlusionMap ImageTexture {
                      url [
                        "https://raw.githubusercontent.com/cyberbotics/webots/R2022b/projects/robots/universal_robots/protos/UR10e/textures/occlusion_1.jpg"
                      ]
                    }
                  }
                  geometry Mesh {
                    url [
                      "https://raw.githubusercontent.com/cyberbotics/webots/R2022b/projects/robots/universal_robots/protos/UR10e/meshes/upper_arm_link_3.obj"
                    ]
                  }
                }
                Shape {
                  appearance PBRAppearance {
                    baseColor 0.490196 0.678431 0.8
                    roughness 0.96875
                    metalness 0
                    normalMap ImageTexture {
                      url [
                        "https://raw.githubusercontent.com/cyberbotics/webots/R2022b/projects/robots/universal_robots/protos/UR10e/textures/normal_2.jpg"
                      ]
                    }
                    occlusionMap ImageTexture {
                      url [
                        "https://raw.githubusercontent.com/cyberbotics/webots/R2022b/projects/robots/universal_robots/protos/UR10e/textures/occlusion_2.jpg"
                      ]
                    }
                  }
                  geometry Mesh {
                    url [
                      "https://raw.githubusercontent.com/cyberbotics/webots/R2022b/projects/robots/universal_robots/protos/UR10e/meshes/upper_arm_link_4.obj"
                    ]
                  }
                }
                Shape {
                  appearance USE METAL_APPEARANCE
                  geometry Mesh {
                    url [
                      "https://raw.githubusercontent.com/cyberbotics/webots/R2022b/projects/robots/universal_robots/protos/UR10e/meshes/upper_arm_link_5.obj"
                    ]
                  }
                }
                Shape {
                  appearance USE JOINT_APPEARANCE
                  geometry Mesh {
                    url [
                      "https://raw.githubusercontent.com/cyberbotics/webots/R2022b/projects/robots/universal_robots/protos/UR10e/meshes/upper_arm_link_6.obj"
                    ]
                  }
                }
                Shape {
                  appearance USE METAL_APPEARANCE
                  geometry Mesh {
                    url [
                      "https://raw.githubusercontent.com/cyberbotics/webots/R2022b/projects/robots/universal_robots/protos/UR10e/meshes/upper_arm_link_7.obj"
                    ]
                  }
                }
                Shape {
                  appearance USE JOINT_APPEARANCE
                  geometry Mesh {
                    url [
                      "https://raw.githubusercontent.com/cyberbotics/webots/R2022b/projects/robots/universal_robots/protos/UR10e/meshes/upper_arm_link_8.obj"
                    ]
                  }
                }
                Shape {
                  appearance USE JOINT_APPEARANCE
                  geometry Mesh {
                    url [
                      "https://raw.githubusercontent.com/cyberbotics/webots/R2022b/projects/robots/universal_robots/protos/UR10e/meshes/upper_arm_link_9.obj"
                    ]
                  }
                }
                HingeJoint {
                  jointParameters HingeJointParameters {
                    position -1.2603429532230919
                    axis 0 1 0
                    anchor 0 -0.137 0.613
                  }
                  device [
                    RotationalMotor {
                      name "elbow_joint"
                      maxVelocity 3.14
                      minPosition -3.14159265359
                      maxPosition 3.14159265359
                      maxTorque 150
                    }
                    PositionSensor {
                      name "elbow_joint_sensor"
                    }
                  ]
                  endPoint Solid {
                    translation 0 -0.137 0.613
                    rotation 0 -1 0 1.2603429532230919
                    children [
                      Shape {
                        appearance USE SCREW_APPEARANCE
                        geometry Mesh {
                          url [
                            "https://raw.githubusercontent.com/cyberbotics/webots/R2022b/projects/robots/universal_robots/protos/UR10e/meshes/forearm_link_0.obj"
                          ]
                        }
                      }
                      Shape {
                        appearance USE METAL_APPEARANCE_LIGHT
                        geometry Mesh {
                          url [
                            "https://raw.githubusercontent.com/cyberbotics/webots/R2022b/projects/robots/universal_robots/protos/UR10e/meshes/forearm_link_1.obj"
                          ]
                        }
                      }
                      Shape {
                        appearance USE METAL_APPEARANCE
                        geometry Mesh {
                          url [
                            "https://raw.githubusercontent.com/cyberbotics/webots/R2022b/projects/robots/universal_robots/protos/UR10e/meshes/forearm_link_2.obj"
                          ]
                        }
                      }
                      Shape {
                        appearance USE JOINT_APPEARANCE
                        geometry Mesh {
                          url [
                            "https://raw.githubusercontent.com/cyberbotics/webots/R2022b/projects/robots/universal_robots/protos/UR10e/meshes/forearm_link_3.obj"
                          ]
                        }
                      }
                      Shape {
                        appearance PBRAppearance {
                          baseColor 0.490196 0.678431 0.8
                          roughness 0.96875
                          metalness 0
                          normalMap ImageTexture {
                            url [
                              "https://raw.githubusercontent.com/cyberbotics/webots/R2022b/projects/robots/universal_robots/protos/UR10e/textures/normal_3.jpg"
                            ]
                          }
                          occlusionMap ImageTexture {
                            url [
                              "https://raw.githubusercontent.com/cyberbotics/webots/R2022b/projects/robots/universal_robots/protos/UR10e/textures/occlusion_3.jpg"
                            ]
                          }
                        }
                        geometry Mesh {
                          url [
                            "https://raw.githubusercontent.com/cyberbotics/webots/R2022b/projects/robots/universal_robots/protos/UR10e/meshes/forearm_link_4.obj"
                          ]
                        }
                      }
                      Shape {
                        appearance USE METAL_APPEARANCE
                        geometry Mesh {
                          url [
                            "https://raw.githubusercontent.com/cyberbotics/webots/R2022b/projects/robots/universal_robots/protos/UR10e/meshes/forearm_link_5.obj"
                          ]
                        }
                      }
                      Shape {
                        appearance USE JOINT_APPEARANCE
                        geometry Mesh {
                          url [
                            "https://raw.githubusercontent.com/cyberbotics/webots/R2022b/projects/robots/universal_robots/protos/UR10e/meshes/forearm_link_6.obj"
                          ]
                        }
                      }
                      Shape {
                        appearance USE JOINT_APPEARANCE
                        geometry Mesh {
                          url [
                            "https://raw.githubusercontent.com/cyberbotics/webots/R2022b/projects/robots/universal_robots/protos/UR10e/meshes/forearm_link_7.obj"
                          ]
                        }
                      }
                      HingeJoint {
                        jointParameters HingeJointParameters {
                          position 2.0598628291524097
                          axis 0 1 0
                          anchor 0 0 0.571
                        }
                        device [
                          RotationalMotor {
                            name "wrist_1_joint"
                            maxVelocity 6.28
                            minPosition -6.28318530718
                            maxPosition 6.28318530718
                            maxTorque 54
                          }
                          PositionSensor {
                            name "wrist_1_joint_sensor"
                          }
                        ]
                        endPoint Solid {
                          translation 0 0 0.571
                          rotation 0 1 0 3.6306588291524093
                          children [
                            Shape {
                              appearance USE SCREW_APPEARANCE
                              geometry Mesh {
                                url [
                                  "https://raw.githubusercontent.com/cyberbotics/webots/R2022b/projects/robots/universal_robots/protos/UR10e/meshes/wrist_1_link_0.obj"
                                ]
                              }
                            }
                            Shape {
                              appearance USE METAL_APPEARANCE
                              geometry Mesh {
                                url [
                                  "https://raw.githubusercontent.com/cyberbotics/webots/R2022b/projects/robots/universal_robots/protos/UR10e/meshes/wrist_1_link_1.obj"
                                ]
                              }
                            }
                            Shape {
                              appearance PBRAppearance {
                                baseColor 0.490196 0.678431 0.8
                                roughness 0.96875
                                metalness 0
                                normalMap ImageTexture {
                                  url [
                                    "https://raw.githubusercontent.com/cyberbotics/webots/R2022b/projects/robots/universal_robots/protos/UR10e/textures/normal_4.jpg"
                                  ]
                                }
                                occlusionMap ImageTexture {
                                  url [
                                    "https://raw.githubusercontent.com/cyberbotics/webots/R2022b/projects/robots/universal_robots/protos/UR10e/textures/occlusion_4.jpg"
                                  ]
                                }
                              }
                              geometry Mesh {
                                url [
                                  "https://raw.githubusercontent.com/cyberbotics/webots/R2022b/projects/robots/universal_robots/protos/UR10e/meshes/wrist_1_link_2.obj"
                                ]
                              }
                            }
                            Shape {
                              appearance USE JOINT_APPEARANCE
                              geometry Mesh {
                                url [
                                  "https://raw.githubusercontent.com/cyberbotics/webots/R2022b/projects/robots/universal_robots/protos/UR10e/meshes/wrist_1_link_3.obj"
                                ]
                              }
                            }
                            HingeJoint {
                              jointParameters HingeJointParameters {
                                position 1.5708052679957945
                                axis 0 0 1
                                anchor 0 0.135 0
                              }
                              device [
                                RotationalMotor {
                                  name "wrist_2_joint"
                                  maxVelocity 6.28
                                  minPosition -6.28318530718
                                  maxPosition 6.28318530718
                                  maxTorque 54
                                }
                                PositionSensor {
                                  name "wrist_2_joint_sensor"
                                }
                              ]
                              endPoint Solid {
                                translation 0 0.135 0
                                rotation 0 0 1 1.5708052679957942
                                children [
                                  Shape {
                                    appearance USE SCREW_APPEARANCE
                                    geometry Mesh {
                                      url [
                                        "https://raw.githubusercontent.com/cyberbotics/webots/R2022b/projects/robots/universal_robots/protos/UR10e/meshes/wrist_2_link_0.obj"
                                      ]
                                    }
                                  }
                                  Shape {
                                    appearance USE METAL_APPEARANCE
                                    geometry Mesh {
                                      url [
                                        "https://raw.githubusercontent.com/cyberbotics/webots/R2022b/projects/robots/universal_robots/protos/UR10e/meshes/wrist_2_link_1.obj"
                                      ]
                                    }
                                  }
                                  Shape {
                                    appearance PBRAppearance {
                                      baseColor 0.490196 0.678431 0.8
                                      roughness 0.96875
                                      metalness 0
                                      normalMap ImageTexture {
                                        url [
                                          "https://raw.githubusercontent.com/cyberbotics/webots/R2022b/projects/robots/universal_robots/protos/UR10e/textures/normal_5.jpg"
                                        ]
                                      }
                                      occlusionMap ImageTexture {
                                        url [
                                          "https://raw.githubusercontent.com/cyberbotics/webots/R2022b/projects/robots/universal_robots/protos/UR10e/textures/occlusion_5.jpg"
                                        ]
                                      }
                                    }
                                    geometry Mesh {
                                      url [
                                        "https://raw.githubusercontent.com/cyberbotics/webots/R2022b/projects/robots/universal_robots/protos/UR10e/meshes/wrist_2_link_2.obj"
                                      ]
                                    }
                                  }
                                  Shape {
                                    appearance USE JOINT_APPEARANCE
                                    geometry Mesh {
                                      url [
                                        "https://raw.githubusercontent.com/cyberbotics/webots/R2022b/projects/robots/universal_robots/protos/UR10e/meshes/wrist_2_link_3.obj"
                                      ]
                                    }
                                  }
                                  HingeJoint {
                                    jointParameters HingeJointParameters {
                                      position -1.0392256605357546
                                      axis 0 1 0
                                      anchor 0 0 0.12
                                    }
                                    device [
                                      RotationalMotor {
                                        name "wrist_3_joint"
                                        maxVelocity 6.28
                                        minPosition -6.28318530718
                                        maxPosition 6.28318530718
                                        maxTorque 54
                                      }
                                      PositionSensor {
                                        name "wrist_3_joint_sensor"
                                      }
                                    ]
                                    endPoint Solid {
                                      translation 0 0 0.12
                                      rotation 0 -0.9999999999999999 0 1.0392256605357548
                                      children [
                                        Shape {
                                          appearance USE METAL_APPEARANCE
                                          geometry Mesh {
                                            url [
                                              "https://raw.githubusercontent.com/cyberbotics/webots/R2022b/projects/robots/universal_robots/protos/UR10e/meshes/wrist_3_link_0.obj"
                                            ]
                                          }
                                        }
                                        Pose {
                                          translation 0 0.12 0
                                          children [
                                            Robotiq3fGripper {
                                              hidden position_0_0 4.5592772338371697e-07
                                              hidden position_0_1 -2.1847473079369657e-05
                                              hidden position_0_2 0.04949993550404313
                                              hidden rotation_1 0.706825225059518 0.7073882252409698 3.161131595756374e-06 3.141598322517838
                                              hidden position_1_0 0.04951148573238064
                                              hidden rotation_2 0 0 0.9999999999999999 1.1485692868887892e-05
                                              hidden position_2_0 -9.523968709196456e-09
                                              hidden rotation_3 0 0 -1 0.5200000095239665
                                              hidden position_3_0 -0.052299999999973215
                                              hidden rotation_5 0.7068252251085576 0.7073882251832776 -4.721173148771603e-06 3.1415825453579225
                                              hidden position_5_0 0.04951148445792637
                                              hidden rotation_6 0 0 1 1.1484300860536212e-05
                                              hidden position_6_0 -9.523689168243542e-09
                                              hidden rotation_7 0 0 -1 0.5200000095236875
                                              hidden position_7_0 -0.05229999999998879
                                              hidden rotation_9 0 0 -1 6.664001874625056e-08
                                              hidden position_9_0 -9.51313516850405e-09
                                              hidden rotation_10 0 0 -1 0.5200000095131346
                                              hidden position_10_0 -0.05230000000000753
                                            }
                                          ]
                                        }
                                      ]
                                      name "wrist_3_link"
                                      boundingObject Group {
                                        children [
                                          Pose {
                                            translation 0 0.086 0
                                            rotation 1 0 0 -1.570796
                                            children [
                                              Cylinder {
                                                height 0.048
                                                radius 0.045
                                              }
                                            ]
                                          }
                                          Pose {
                                            translation 0 0.109 0
                                            rotation 1 0 0 -1.570796
                                            children [
                                              Cylinder {
                                                height 0.018
                                                radius 0.032
                                              }
                                            ]
                                          }
                                        ]
                                      }
                                      physics Physics {
                                        density -1
                                        mass 0.615
                                        centerOfMass [
                                          0 0 0
                                        ]
                                      }
                                      linearVelocity 8.975137279774348e-06 6.515999358137955e-06 1.0146068606320275e-05
                                      angularVelocity -5.466372893630597e-05 0.00010781447889383471 4.605110612126303e-06
                                    }
                                  }
                                ]
                                name "wrist_2_link"
                                boundingObject Group {
                                  children [
                                    Pose {
                                      translation 0 0.007 0.1195
                                      rotation 1 0 0 -1.570796
                                      children [
                                        Cylinder {
                                          height 0.12
                                          radius 0.047
                                        }
                                      ]
                                    }
                                    Pose {
                                      translation 0 0 0.0805
                                      rotation 1 0 0 3.141593
                                      children [
                                        Cylinder {
                                          height 0.043
                                          radius 0.046
                                        }
                                      ]
                                    }
                                  ]
                                }
                                physics Physics {
                                  density -1
                                  mass 1.98
                                  centerOfMass [
                                    0 0.007 0.119
                                  ]
                                }
                                linearVelocity -9.658079965133904e-07 1.4858725034815583e-06 1.0061134536949981e-05
                                angularVelocity -5.466757638375013e-05 0.00010781464811547273 5.763898601368536e-08
                              }
                            }
                          ]
                          name "wrist_1_link"
                          boundingObject Group {
                            children [
                              Pose {
                                translation 0 0.095 0
                                rotation 1 0 0 -1.570796
                                children [
                                  Cylinder {
                                    height 0.075
                                    radius 0.045
                                  }
                                ]
                              }
                              Pose {
                                translation 0 0.134 0.007
                                rotation 1 0 0 3.141593
                                children [
                                  Cylinder {
                                    height 0.126
                                    radius 0.048
                                  }
                                ]
                              }
                            ]
                          }
                          physics Physics {
                            density -1
                            mass 2.1
                            centerOfMass [
                              0 0.118 0.007
                            ]
                          }
                          linearVelocity -2.0376281919675654e-06 1.1029494437385165e-06 6.313988715299314e-07
                          angularVelocity 2.738270492256103e-05 7.9563173632608e-05 2.185479493042845e-08
                        }
                      }
                    ]
                    name "forearm_link"
                    boundingObject Group {
                      children [
                        Pose {
                          translation 0 0 0.307
                          rotation 1 0 0 3.141593
                          children [
                            Cylinder {
                              height 0.49
                              radius 0.047
                            }
                          ]
                        }
                        Pose {
                          translation 0 0.009 0.57
                          rotation 1 0 0 -1.570796
                          children [
                            Cylinder {
                              height 0.129
                              radius 0.046
                            }
                          ]
                        }
                        Pose {
                          translation 0 0.06 0
                          rotation 1 0 0 -1.570796
                          children [
                            Capsule {
                              height 0.05
                              radius 0.058
                              subdivision 16
                            }
                          ]
                        }
                        Pose {
                          translation 0 0 0.05
                          children [
                            Capsule {
                              height 0.03
                              radius 0.057
                              subdivision 16
                            }
                          ]
                        }
                      ]
                    }
                    physics Physics {
                      density -1
                      mass 3.989
                      centerOfMass [
                        0 0 0
                      ]
                    }
                    linearVelocity -8.896170936419959e-07 5.322572734402819e-07 1.4076067041757247e-08
                    angularVelocity -2.4483435234840928e-08 -3.7897543317760026e-08 1.5113830574861638e-08
                  }
                }
              ]
              name "upper_arm_link"
              boundingObject Group {
                children [
                  Pose {
                    translation 0 0 0.33
                    rotation 1 0 0 3.141593
                    children [
                      Cylinder {
                        height 0.463
                        radius 0.058
                      }
                    ]
                  }
                  Pose {
                    translation 0 0 0.06
                    rotation 1 0 0 3.141593
                    children [
                      Cylinder {
                        height 0.1
                        radius 0.076
                      }
                    ]
                  }
                  Pose {
                    rotation 1 0 0 -1.570796
                    children [
                      Cylinder {
                        height 0.183
                        radius 0.077
                      }
                    ]
                  }
                  Pose {
                    translation 0 -0.005 0.612
                    rotation 1 0 0 -1.570796
                    children [
                      Cylinder {
                        height 0.149
                        radius 0.061
                      }
                    ]
                  }
                ]
              }
              physics Physics {
                density -1
                mass 13.051
                centerOfMass [
                  0 0 0.3065
                ]
              }
              linearVelocity -3.153133724251264e-07 7.143979673137271e-07 1.0492164925951177e-08
              angularVelocity -2.7511728650718326e-08 -1.0210615258687612e-09 -1.218240762767798e-08
            }
          }
        ]
        name "shoulder_link"
        boundingObject Group {
          children [
            Pose {
              rotation 1 0 0 3.141593
              children [
                Cylinder {
                  height 0.183
                  radius 0.077
                }
              ]
            }
            Pose {
              translation 0 0.05 0
              rotation 1 0 0 1.570797
              children [
                Cylinder {
                  height 0.093
                  radius 0.076
                }
              ]
            }
          ]
        }
        physics Physics {
          density -1
          mass 7.369
          centerOfMass [
            0 0 0
          ]
        }
        linearVelocity 8.508719066115849e-08 7.87291702654504e-08 4.223240128743272e-09
        angularVelocity 1.6628897938495457e-09 1.812166704904435e-09 -8.036094490567616e-08
      }
    }
  ]
  name "UR10e"
  model "UR10e"
  boundingObject Pose {
    translation 0 0 0.05
    rotation 1 0 0 3.141593
    children [
      Cylinder {
        height 0.1
        radius 0.095
      }
    ]
  }
  controller "Control_UR10_v1_basic_controler"
  selfCollision TRUE
}
