#VRML_SIM R2023b utf8

EXTERNPROTO "https://raw.githubusercontent.com/cyberbotics/webots/R2022b/projects/objects/backgrounds/protos/TexturedBackground.proto"
EXTERNPROTO "https://raw.githubusercontent.com/cyberbotics/webots/R2022b/projects/objects/backgrounds/protos/TexturedBackgroundLight.proto"
EXTERNPROTO "https://raw.githubusercontent.com/cyberbotics/webots/R2022b/projects/objects/floors/protos/RectangleArena.proto"
EXTERNPROTO "https://raw.githubusercontent.com/cyberbotics/webots/R2022b/projects/devices/robotiq/protos/Robotiq3fGripper.proto"

WorldInfo {
}
Viewpoint {
  orientation 0.17117152053257662 -0.19438394530082445 -0.9658753503262477 4.804689767167089
  position 0.30093426317010197 -2.379166857142672 1.2221782412757394
}
TexturedBackground {
}
TexturedBackgroundLight {
}
Solid {
  translation 0.49 -0.75 0
  children [
    Shape {
      appearance PBRAppearance {
      }
      geometry Box {
        size 0.1 0.1 0.1
      }
    }
  ]
}
RectangleArena {
  translation -0.0896051 0.211151 0
  floorSize 10 10
}
Robot {
  rotation 0 0 1 3.14159
  children [
    Pose {
      translation -0.0602 0.0601 0.0252
      rotation 1 0 0 -3.1415923071795864
      children [
        DEF SCREW Group {
          children [
            Transform {
              scale 1.1 1.1 1.1
              children [
                Shape {
                  appearance PBRAppearance {
                    baseColorMap ImageTexture {
                      url [
                        "https://raw.githubusercontent.com/cyberbotics/webots/R2022b/projects/appearances/protos/textures/old_steel/old_steel_base_color.jpg"
                      ]
                    }
                    roughnessMap ImageTexture {
                      url [
                        "https://raw.githubusercontent.com/cyberbotics/webots/R2022b/projects/appearances/protos/textures/old_steel/old_steel_roughness.jpg"
                      ]
                    }
                    metalnessMap ImageTexture {
                      url [
                        "https://raw.githubusercontent.com/cyberbotics/webots/R2022b/projects/appearances/protos/textures/old_steel/old_steel_metalness.jpg"
                      ]
                    }
                    normalMap ImageTexture {
                      url [
                        "https://raw.githubusercontent.com/cyberbotics/webots/R2022b/projects/appearances/protos/textures/old_steel/old_steel_normal.jpg"
                      ]
                    }
                  }
                  geometry Mesh {
                    url [
                      "https://raw.githubusercontent.com/cyberbotics/webots/R2022b/projects/robots/universal_robots/protos/UR10e/meshes/screw.obj"
                    ]
                  }
                }
              ]
            }
            DEF CYLINDER Pose {
              translation 0 0 0.02
              rotation -0.7071067811865476 0.7071067811865476 0 -3.141593
              children [
                Shape {
                  appearance PBRAppearance {
                    baseColorMap ImageTexture {
                      url [
                        "https://raw.githubusercontent.com/cyberbotics/webots/R2022b/projects/appearances/protos/textures/screw_thread/screw_thread_base_color.jpg"
                      ]
                    }
                    roughnessMap ImageTexture {
                      url [
                        "https://raw.githubusercontent.com/cyberbotics/webots/R2022b/projects/appearances/protos/textures/screw_thread/screw_thread_roughness.jpg"
                      ]
                    }
                    normalMap ImageTexture {
                      url [
                        "https://raw.githubusercontent.com/cyberbotics/webots/R2022b/projects/appearances/protos/textures/screw_thread/screw_thread_normal.jpg"
                      ]
                    }
                    occlusionMap ImageTexture {
                      url [
                        "https://raw.githubusercontent.com/cyberbotics/webots/R2022b/projects/appearances/protos/textures/screw_thread/screw_thread_occlusion.jpg"
                      ]
                    }
                    textureTransform TextureTransform {
                      rotation 1.5708
                      scale 1.6 2
                    }
                  }
                  geometry Cylinder {
                    height 0.04
                    radius 0.0044
                  }
                }
              ]
            }
          ]
        }
      ]
    }
    Pose {
      translation -0.0602 -0.0602 0.0252
      rotation 1 0 0 -3.1415923071795864
      children [
        USE SCREW
      ]
    }
    Pose {
      translation 0.0602 -0.0602 0.0252
      rotation 1 0 0 -3.1415923071795864
      children [
        USE SCREW
      ]
    }
    Pose {
      translation 0.0602 0.0602 0.0252
      rotation 1 0 0 -3.1415923071795864
      children [
        USE SCREW
      ]
    }
    Shape {
      appearance DEF METAL_APPEARANCE PBRAppearance {
        baseColor 0.6 0.6 0.6
        roughness 0.7
      }
      geometry Mesh {
        url [
          "https://raw.githubusercontent.com/cyberbotics/webots/R2022b/projects/robots/universal_robots/protos/UR10e/meshes/base_link_0.obj"
        ]
      }
    }
    Shape {
      appearance DEF JOINT_APPEARANCE PBRAppearance {
        baseColor 0 0 0
        roughness 1
        metalness 0
      }
      geometry Mesh {
        url [
          "https://raw.githubusercontent.com/cyberbotics/webots/R2022b/projects/robots/universal_robots/protos/UR10e/meshes/base_link_1.obj"
        ]
      }
    }
    HingeJoint {
      jointParameters HingeJointParameters {
        position 2.809865142604054
        axis 0 0 1
        anchor 0 0 0.181
      }
      device [
        RotationalMotor {
          name "shoulder_pan_joint"
          maxVelocity 3.14
          minPosition -6.28318530718
          maxPosition 6.28318530718
          maxTorque 330
        }
        PositionSensor {
          name "shoulder_pan_joint_sensor"
        }
      ]
      endPoint Solid {
        translation 0 0 0.181
        rotation 0 0 1 5.951450449783651
        children [
          Shape {
            appearance DEF SCREW_APPEARANCE PBRAppearance {
            }
            geometry Mesh {
              url [
                "https://raw.githubusercontent.com/cyberbotics/webots/R2022b/projects/robots/universal_robots/protos/UR10e/meshes/shoulder_link_0.obj"
              ]
            }
          }
          Shape {
            appearance USE METAL_APPEARANCE
            geometry Mesh {
              url [
                "https://raw.githubusercontent.com/cyberbotics/webots/R2022b/projects/robots/universal_robots/protos/UR10e/meshes/shoulder_link_1.obj"
              ]
            }
          }
          Shape {
            appearance USE JOINT_APPEARANCE
            geometry Mesh {
              url [
                "https://raw.githubusercontent.com/cyberbotics/webots/R2022b/projects/robots/universal_robots/protos/UR10e/meshes/shoulder_link_2.obj"
              ]
            }
          }
          Shape {
            appearance PBRAppearance {
              baseColor 0.490196 0.678431 0.8
              roughness 0.96875
              metalness 0
              normalMap ImageTexture {
                url [
                  "https://raw.githubusercontent.com/cyberbotics/webots/R2022b/projects/robots/universal_robots/protos/UR10e/textures/normal_0.jpg"
                ]
              }
              occlusionMap ImageTexture {
                url [
                  "https://raw.githubusercontent.com/cyberbotics/webots/R2022b/projects/robots/universal_robots/protos/UR10e/textures/occlusion_0.jpg"
                ]
              }
            }
            geometry Mesh {
              url [
                "https://raw.githubusercontent.com/cyberbotics/webots/R2022b/projects/robots/universal_robots/protos/UR10e/meshes/shoulder_link_3.obj"
              ]
            }
          }
          HingeJoint {
            jointParameters HingeJointParameters {
              position -2.3711155909041137
              axis 0 1 0
              anchor 0 0.176 0
            }
            device [
              RotationalMotor {
                name "shoulder_lift_joint"
                maxVelocity 3.14
                minPosition -6.28318530718
                maxPosition 6.28318530718
                maxTorque 330
              }
              PositionSensor {
                name "shoulder_lift_joint_sensor"
              }
            ]
            endPoint Solid {
              translation 0 0.176 0
              rotation 0 -1 0 0.8003195909041131
              children [
                Shape {
                  appearance USE SCREW_APPEARANCE
                  geometry Mesh {
                    url [
                      "https://raw.githubusercontent.com/cyberbotics/webots/R2022b/projects/robots/universal_robots/protos/UR10e/meshes/upper_arm_link_0.obj"
                    ]
                  }
                }
                Shape {
                  appearance USE SCREW_APPEARANCE
                  geometry Mesh {
                    url [
                      "https://raw.githubusercontent.com/cyberbotics/webots/R2022b/projects/robots/universal_robots/protos/UR10e/meshes/upper_arm_link_1.obj"
                    ]
                  }
                }
                Shape {
                  appearance DEF METAL_APPEARANCE_LIGHT PBRAppearance {
                    roughness 0.7
                  }
                  geometry Mesh {
                    url [
                      "https://raw.githubusercontent.com/cyberbotics/webots/R2022b/projects/robots/universal_robots/protos/UR10e/meshes/upper_arm_link_2.obj"
                    ]
                  }
                }
                Shape {
                  appearance PBRAppearance {
                    baseColor 0.490196 0.678431 0.8
                    roughness 0.96875
                    metalness 0
                    normalMap ImageTexture {
                      url [
                        "https://raw.githubusercontent.com/cyberbotics/webots/R2022b/projects/robots/universal_robots/protos/UR10e/textures/normal_1.jpg"
                      ]
                    }
                    occlusionMap ImageTexture {
                      url [
                        "https://raw.githubusercontent.com/cyberbotics/webots/R2022b/projects/robots/universal_robots/protos/UR10e/textures/occlusion_1.jpg"
                      ]
                    }
                  }
                  geometry Mesh {
                    url [
                      "https://raw.githubusercontent.com/cyberbotics/webots/R2022b/projects/robots/universal_robots/protos/UR10e/meshes/upper_arm_link_3.obj"
                    ]
                  }
                }
                Shape {
                  appearance PBRAppearance {
                    baseColor 0.490196 0.678431 0.8
                    roughness 0.96875
                    metalness 0
                    normalMap ImageTexture {
                      url [
                        "https://raw.githubusercontent.com/cyberbotics/webots/R2022b/projects/robots/universal_robots/protos/UR10e/textures/normal_2.jpg"
                      ]
                    }
                    occlusionMap ImageTexture {
                      url [
                        "https://raw.githubusercontent.com/cyberbotics/webots/R2022b/projects/robots/universal_robots/protos/UR10e/textures/occlusion_2.jpg"
                      ]
                    }
                  }
                  geometry Mesh {
                    url [
                      "https://raw.githubusercontent.com/cyberbotics/webots/R2022b/projects/robots/universal_robots/protos/UR10e/meshes/upper_arm_link_4.obj"
                    ]
                  }
                }
                Shape {
                  appearance USE METAL_APPEARANCE
                  geometry Mesh {
                    url [
                      "https://raw.githubusercontent.com/cyberbotics/webots/R2022b/projects/robots/universal_robots/protos/UR10e/meshes/upper_arm_link_5.obj"
                    ]
                  }
                }
                Shape {
                  appearance USE JOINT_APPEARANCE
                  geometry Mesh {
                    url [
                      "https://raw.githubusercontent.com/cyberbotics/webots/R2022b/projects/robots/universal_robots/protos/UR10e/meshes/upper_arm_link_6.obj"
                    ]
                  }
                }
                Shape {
                  appearance USE METAL_APPEARANCE
                  geometry Mesh {
                    url [
                      "https://raw.githubusercontent.com/cyberbotics/webots/R2022b/projects/robots/universal_robots/protos/UR10e/meshes/upper_arm_link_7.obj"
                    ]
                  }
                }
                Shape {
                  appearance USE JOINT_APPEARANCE
                  geometry Mesh {
                    url [
                      "https://raw.githubusercontent.com/cyberbotics/webots/R2022b/projects/robots/universal_robots/protos/UR10e/meshes/upper_arm_link_8.obj"
                    ]
                  }
                }
                Shape {
                  appearance USE JOINT_APPEARANCE
                  geometry Mesh {
                    url [
                      "https://raw.githubusercontent.com/cyberbotics/webots/R2022b/projects/robots/universal_robots/protos/UR10e/meshes/upper_arm_link_9.obj"
                    ]
                  }
                }
                HingeJoint {
                  jointParameters HingeJointParameters {
                    position -1.260495678299886
                    axis 0 1 0
                    anchor 0 -0.137 0.613
                  }
                  device [
                    RotationalMotor {
                      name "elbow_joint"
                      maxVelocity 3.14
                      minPosition -3.14159265359
                      maxPosition 3.14159265359
                      maxTorque 150
                    }
                    PositionSensor {
                      name "elbow_joint_sensor"
                    }
                  ]
                  endPoint Solid {
                    translation 0 -0.137 0.613
                    rotation 0 -0.9999999999999999 0 1.2604956782998862
                    children [
                      Shape {
                        appearance USE SCREW_APPEARANCE
                        geometry Mesh {
                          url [
                            "https://raw.githubusercontent.com/cyberbotics/webots/R2022b/projects/robots/universal_robots/protos/UR10e/meshes/forearm_link_0.obj"
                          ]
                        }
                      }
                      Shape {
                        appearance USE METAL_APPEARANCE_LIGHT
                        geometry Mesh {
                          url [
                            "https://raw.githubusercontent.com/cyberbotics/webots/R2022b/projects/robots/universal_robots/protos/UR10e/meshes/forearm_link_1.obj"
                          ]
                        }
                      }
                      Shape {
                        appearance USE METAL_APPEARANCE
                        geometry Mesh {
                          url [
                            "https://raw.githubusercontent.com/cyberbotics/webots/R2022b/projects/robots/universal_robots/protos/UR10e/meshes/forearm_link_2.obj"
                          ]
                        }
                      }
                      Shape {
                        appearance USE JOINT_APPEARANCE
                        geometry Mesh {
                          url [
                            "https://raw.githubusercontent.com/cyberbotics/webots/R2022b/projects/robots/universal_robots/protos/UR10e/meshes/forearm_link_3.obj"
                          ]
                        }
                      }
                      Shape {
                        appearance PBRAppearance {
                          baseColor 0.490196 0.678431 0.8
                          roughness 0.96875
                          metalness 0
                          normalMap ImageTexture {
                            url [
                              "https://raw.githubusercontent.com/cyberbotics/webots/R2022b/projects/robots/universal_robots/protos/UR10e/textures/normal_3.jpg"
                            ]
                          }
                          occlusionMap ImageTexture {
                            url [
                              "https://raw.githubusercontent.com/cyberbotics/webots/R2022b/projects/robots/universal_robots/protos/UR10e/textures/occlusion_3.jpg"
                            ]
                          }
                        }
                        geometry Mesh {
                          url [
                            "https://raw.githubusercontent.com/cyberbotics/webots/R2022b/projects/robots/universal_robots/protos/UR10e/meshes/forearm_link_4.obj"
                          ]
                        }
                      }
                      Shape {
                        appearance USE METAL_APPEARANCE
                        geometry Mesh {
                          url [
                            "https://raw.githubusercontent.com/cyberbotics/webots/R2022b/projects/robots/universal_robots/protos/UR10e/meshes/forearm_link_5.obj"
                          ]
                        }
                      }
                      Shape {
                        appearance USE JOINT_APPEARANCE
                        geometry Mesh {
                          url [
                            "https://raw.githubusercontent.com/cyberbotics/webots/R2022b/projects/robots/universal_robots/protos/UR10e/meshes/forearm_link_6.obj"
                          ]
                        }
                      }
                      Shape {
                        appearance USE JOINT_APPEARANCE
                        geometry Mesh {
                          url [
                            "https://raw.githubusercontent.com/cyberbotics/webots/R2022b/projects/robots/universal_robots/protos/UR10e/meshes/forearm_link_7.obj"
                          ]
                        }
                      }
                      HingeJoint {
                        jointParameters HingeJointParameters {
                          position 5.679884913310164
                          axis 0 1 0
                          anchor 0 0 0.571
                        }
                        device [
                          RotationalMotor {
                            name "wrist_1_joint"
                            maxVelocity 6.28
                            minPosition -6.28318530718
                            maxPosition 6.28318530718
                            maxTorque 54
                          }
                          PositionSensor {
                            name "wrist_1_joint_sensor"
                          }
                        ]
                        endPoint Solid {
                          translation 0.00018868763083197058 2.8191668159580066e-06 0.571209753072837
                          rotation 0 -1 0 5.723296793677047
                          children [
                            Shape {
                              appearance USE SCREW_APPEARANCE
                              geometry Mesh {
                                url [
                                  "https://raw.githubusercontent.com/cyberbotics/webots/R2022b/projects/robots/universal_robots/protos/UR10e/meshes/wrist_1_link_0.obj"
                                ]
                              }
                            }
                            Shape {
                              appearance USE METAL_APPEARANCE
                              geometry Mesh {
                                url [
                                  "https://raw.githubusercontent.com/cyberbotics/webots/R2022b/projects/robots/universal_robots/protos/UR10e/meshes/wrist_1_link_1.obj"
                                ]
                              }
                            }
                            Shape {
                              appearance PBRAppearance {
                                baseColor 0.490196 0.678431 0.8
                                roughness 0.96875
                                metalness 0
                                normalMap ImageTexture {
                                  url [
                                    "https://raw.githubusercontent.com/cyberbotics/webots/R2022b/projects/robots/universal_robots/protos/UR10e/textures/normal_4.jpg"
                                  ]
                                }
                                occlusionMap ImageTexture {
                                  url [
                                    "https://raw.githubusercontent.com/cyberbotics/webots/R2022b/projects/robots/universal_robots/protos/UR10e/textures/occlusion_4.jpg"
                                  ]
                                }
                              }
                              geometry Mesh {
                                url [
                                  "https://raw.githubusercontent.com/cyberbotics/webots/R2022b/projects/robots/universal_robots/protos/UR10e/meshes/wrist_1_link_2.obj"
                                ]
                              }
                            }
                            Shape {
                              appearance USE JOINT_APPEARANCE
                              geometry Mesh {
                                url [
                                  "https://raw.githubusercontent.com/cyberbotics/webots/R2022b/projects/robots/universal_robots/protos/UR10e/meshes/wrist_1_link_3.obj"
                                ]
                              }
                            }
                            HingeJoint {
                              jointParameters HingeJointParameters {
                                position 1.57081461332192
                                axis 0 0 1
                                anchor 0 0.135 0
                              }
                              device [
                                RotationalMotor {
                                  name "wrist_2_joint"
                                  maxVelocity 6.28
                                  minPosition -6.28318530718
                                  maxPosition 6.28318530718
                                  maxTorque 54
                                }
                                PositionSensor {
                                  name "wrist_2_joint_sensor"
                                }
                              ]
                              endPoint Solid {
                                translation -3.281818894555782e-05 0.13500283639329796 0.0002716743415459578
                                rotation -4.88984415425392e-05 -3.7666214655768734e-05 -0.9999999980950994 0.13099553493056898
                                children [
                                  Shape {
                                    appearance USE SCREW_APPEARANCE
                                    geometry Mesh {
                                      url [
                                        "https://raw.githubusercontent.com/cyberbotics/webots/R2022b/projects/robots/universal_robots/protos/UR10e/meshes/wrist_2_link_0.obj"
                                      ]
                                    }
                                  }
                                  Shape {
                                    appearance USE METAL_APPEARANCE
                                    geometry Mesh {
                                      url [
                                        "https://raw.githubusercontent.com/cyberbotics/webots/R2022b/projects/robots/universal_robots/protos/UR10e/meshes/wrist_2_link_1.obj"
                                      ]
                                    }
                                  }
                                  Shape {
                                    appearance PBRAppearance {
                                      baseColor 0.490196 0.678431 0.8
                                      roughness 0.96875
                                      metalness 0
                                      normalMap ImageTexture {
                                        url [
                                          "https://raw.githubusercontent.com/cyberbotics/webots/R2022b/projects/robots/universal_robots/protos/UR10e/textures/normal_5.jpg"
                                        ]
                                      }
                                      occlusionMap ImageTexture {
                                        url [
                                          "https://raw.githubusercontent.com/cyberbotics/webots/R2022b/projects/robots/universal_robots/protos/UR10e/textures/occlusion_5.jpg"
                                        ]
                                      }
                                    }
                                    geometry Mesh {
                                      url [
                                        "https://raw.githubusercontent.com/cyberbotics/webots/R2022b/projects/robots/universal_robots/protos/UR10e/meshes/wrist_2_link_2.obj"
                                      ]
                                    }
                                  }
                                  Shape {
                                    appearance USE JOINT_APPEARANCE
                                    geometry Mesh {
                                      url [
                                        "https://raw.githubusercontent.com/cyberbotics/webots/R2022b/projects/robots/universal_robots/protos/UR10e/meshes/wrist_2_link_3.obj"
                                      ]
                                    }
                                  }
                                  HingeJoint {
                                    jointParameters HingeJointParameters {
                                      position -1.039231376667133
                                      axis 0 1 0
                                      anchor 0 0 0.12
                                    }
                                    device [
                                      RotationalMotor {
                                        name "wrist_3_joint"
                                        maxVelocity 6.28
                                        minPosition -6.28318530718
                                        maxPosition 6.28318530718
                                        maxTorque 54
                                      }
                                      PositionSensor {
                                        name "wrist_3_joint_sensor"
                                      }
                                    ]
                                    endPoint Solid {
                                      translation 2.809525381116914e-06 1.887407271972119e-06 0.12026911265249231
                                      rotation 7.763356548888004e-05 -0.9999999958406729 -4.787153597993282e-05 1.4320169640881508
                                      children [
                                        Shape {
                                          appearance USE METAL_APPEARANCE
                                          geometry Mesh {
                                            url [
                                              "https://raw.githubusercontent.com/cyberbotics/webots/R2022b/projects/robots/universal_robots/protos/UR10e/meshes/wrist_3_link_0.obj"
                                            ]
                                          }
                                        }
                                        Pose {
                                          translation 0 0.12 0
                                          children [
                                            Camera {
                                              translation 0 0.12 0
                                              rotation 0 0 1 1.5707996938995747
                                            }
                                            Robotiq3fGripper {
                                              hidden position_0_0 1.6092559844093265e-08
                                              hidden position_0_1 1.6104167783802064e-08
                                              hidden position_0_2 0.04949993563155301
                                              hidden translation_1 -0.0455 0.0214 0.036
                                              hidden rotation_1 0.7068252250609091 0.7073882252402575 3.005688270003635e-06 3.141598011383685
                                              hidden position_1_0 0.0495115031295739
                                              hidden translation_2 0.02 0 0
                                              hidden rotation_2 0 0 1 1.150307876037061e-05
                                              hidden position_2_0 -9.560093161553596e-09
                                              hidden translation_3 0.05 -0.028 0
                                              hidden rotation_3 0 0 -1 0.5200000095600932
                                              hidden position_3_0 -0.052299999999882885
                                              hidden translation_4 0.039 0 0
                                              hidden translation_5 -0.0455 0.0214 -0.036
                                              hidden rotation_5 0.7068252250609104 0.7073882252402562 3.0056923723967627e-06 3.1415980113918964
                                              hidden position_5_0 0.04951150386921074
                                              hidden translation_6 0.02 0 0
                                              hidden rotation_6 0 0 1 1.1503696441666249e-05
                                              hidden position_6_0 -9.561525369328825e-09
                                              hidden translation_7 0.05 -0.028 0
                                              hidden rotation_7 0 0 -1 0.5200000095615253
                                              hidden position_7_0 -0.05229999999989355
                                              hidden translation_8 0.039 0 0
                                              hidden translation_9 0.02 0 0
                                              hidden rotation_9 0 0 -0.9999999999999999 6.664001874625056e-08
                                              hidden position_9_0 -9.494844993661436e-09
                                              hidden translation_10 0.05 -0.028 0
                                              hidden rotation_10 0 0 -1 0.5200000094948429
                                              hidden position_10_0 -0.05230000000006774
                                              hidden translation_11 0.039 0 0
                                            }
                                          ]
                                        }
                                      ]
                                      name "wrist_3_link"
                                      boundingObject Group {
                                        children [
                                          Pose {
                                            translation 0 0.086 0
                                            rotation 1 0 0 -1.570796
                                            children [
                                              Cylinder {
                                                height 0.048
                                                radius 0.045
                                              }
                                            ]
                                          }
                                          Pose {
                                            translation 0 0.109 0
                                            rotation 1 0 0 -1.570796
                                            children [
                                              Cylinder {
                                                height 0.018
                                                radius 0.032
                                              }
                                            ]
                                          }
                                        ]
                                      }
                                      physics Physics {
                                        density -1
                                        mass 0.615
                                        centerOfMass [
                                          0 0 0
                                        ]
                                      }
                                    }
                                  }
                                ]
                                name "wrist_2_link"
                                boundingObject Group {
                                  children [
                                    Pose {
                                      translation 0 0.007 0.1195
                                      rotation 1 0 0 -1.570796
                                      children [
                                        Cylinder {
                                          height 0.12
                                          radius 0.047
                                        }
                                      ]
                                    }
                                    Pose {
                                      translation 0 0 0.0805
                                      rotation 1 0 0 3.141593
                                      children [
                                        Cylinder {
                                          height 0.043
                                          radius 0.046
                                        }
                                      ]
                                    }
                                  ]
                                }
                                physics Physics {
                                  density -1
                                  mass 1.98
                                  centerOfMass [
                                    0 0.007 0.119
                                  ]
                                }
                              }
                            }
                          ]
                          name "wrist_1_link"
                          boundingObject Group {
                            children [
                              Pose {
                                translation 0 0.095 0
                                rotation 1 0 0 -1.570796
                                children [
                                  Cylinder {
                                    height 0.075
                                    radius 0.045
                                  }
                                ]
                              }
                              Pose {
                                translation 0 0.134 0.007
                                rotation 1 0 0 3.141593
                                children [
                                  Cylinder {
                                    height 0.126
                                    radius 0.048
                                  }
                                ]
                              }
                            ]
                          }
                          physics Physics {
                            density -1
                            mass 2.1
                            centerOfMass [
                              0 0.118 0.007
                            ]
                          }
                        }
                      }
                    ]
                    name "forearm_link"
                    boundingObject Group {
                      children [
                        Pose {
                          translation 0 0 0.307
                          rotation 1 0 0 3.141593
                          children [
                            Cylinder {
                              height 0.49
                              radius 0.047
                            }
                          ]
                        }
                        Pose {
                          translation 0 0.009 0.57
                          rotation 1 0 0 -1.570796
                          children [
                            Cylinder {
                              height 0.129
                              radius 0.046
                            }
                          ]
                        }
                        Pose {
                          translation 0 0.06 0
                          rotation 1 0 0 -1.570796
                          children [
                            Capsule {
                              height 0.05
                              radius 0.058
                              subdivision 16
                            }
                          ]
                        }
                        Pose {
                          translation 0 0 0.05
                          children [
                            Capsule {
                              height 0.03
                              radius 0.057
                              subdivision 16
                            }
                          ]
                        }
                      ]
                    }
                    physics Physics {
                      density -1
                      mass 3.989
                      centerOfMass [
                        0 0 0
                      ]
                    }
                  }
                }
              ]
              name "upper_arm_link"
              boundingObject Group {
                children [
                  Pose {
                    translation 0 0 0.33
                    rotation 1 0 0 3.141593
                    children [
                      Cylinder {
                        height 0.463
                        radius 0.058
                      }
                    ]
                  }
                  Pose {
                    translation 0 0 0.06
                    rotation 1 0 0 3.141593
                    children [
                      Cylinder {
                        height 0.1
                        radius 0.076
                      }
                    ]
                  }
                  Pose {
                    rotation 1 0 0 -1.570796
                    children [
                      Cylinder {
                        height 0.183
                        radius 0.077
                      }
                    ]
                  }
                  Pose {
                    translation 0 -0.005 0.612
                    rotation 1 0 0 -1.570796
                    children [
                      Cylinder {
                        height 0.149
                        radius 0.061
                      }
                    ]
                  }
                ]
              }
              physics Physics {
                density -1
                mass 13.051
                centerOfMass [
                  0 0 0.3065
                ]
              }
            }
          }
        ]
        name "shoulder_link"
        boundingObject Group {
          children [
            Pose {
              rotation 1 0 0 3.141593
              children [
                Cylinder {
                  height 0.183
                  radius 0.077
                }
              ]
            }
            Pose {
              translation 0 0.05 0
              rotation 1 0 0 1.570797
              children [
                Cylinder {
                  height 0.093
                  radius 0.076
                }
              ]
            }
          ]
        }
        physics Physics {
          density -1
          mass 7.369
          centerOfMass [
            0 0 0
          ]
        }
      }
    }
  ]
  name "UR10e"
  model "UR10e"
  boundingObject Pose {
    translation 0 0 0.05
    rotation 1 0 0 3.141593
    children [
      Cylinder {
        height 0.1
        radius 0.095
      }
    ]
  }
  controller "Control_UR10_v1_basic_controler"
  selfCollision TRUE
}
